Workbook

Sheet Summary
A1: Leaf-wax biosynthesis empirical validation database
A3: Inventory | B3: Value
A4: Gao 2014 common-garden rows | B4: =COUNTA(Gao2014_Samples!A2:A500) -> 102 | D4: Observation type | E4: Sheets | F4: Model constraint
A5: Tipple 2015 controlled-treatment rows | B5: =COUNTA(Tipple2015_Treatments!A2:A500) -> 24 | D5: Direct leaf water → wax ε | E5: Tipple2015; Liu2016 | F5: Absolute biosynthetic fractionation
A6: Liu 2016 segmented-leaf rows | B6: =COUNTA(Liu2016_Segmented!A2:A500) -> 43 | D6: C27–C33 homolog spacing | E6: Gao2014; Tipple2021_PANGAEA | F6: ER vs plastid reaction/source weighting
A7: Liu 2016 whole-leaf rows | B7: =COUNTA(Liu2016_WholeLeaf!A2:A500) -> 21 | D7: Species variance, common environment | E7: Gao2014 | F7: Hierarchical biochemical prior variance
A8: Tipple 2021 PANGAEA plant rows | B8: =COUNTA(Tipple2021_PANGAEA!A2:A500) -> 97 | D8: Metabolic perturbation | E8: Lehmann2024; Baan2023 | F8: Source-state/reaction physiological modulation
A9: Direct observations | B9: =SUM(B4:B8) -> 287 | D9: Field source/xylem → wax ε | E9: Gao2014; Feakins2016 pending | F9: Leaf + biosynthesis apparent fractionation
A10: Ardenghi 2024 aggregate species-season rows | B10: =COUNTA(Ardenghi2024_Epsilon!A2:A500) -> 27 | D10: MAP → wax ε | E10: Ardenghi2024 | F10: Whole-model apparent fractionation
A11: Studies in registry | B11: =COUNTA(Study_Registry!A2:A100) -> 18 | D11: Wax formation timing | E11: Tipple2013; Sachse2010 | F11: Production/turnover integration

Sheet Gao2014_Samples
A1: Study_ID | B1: Sample_ID | C1: Lineage | D1: Scientific_Name | E1: Growth_Form | F1: C24_n_acid_dD_permil | G1: C26_n_acid_dD_permil | H1: C28_n_acid_dD_permil | I1: C30_n_acid_dD_permil | J1: C27_n_alkane_dD_permil | K1: C29_n_alkane_dD_permil | L1: C31_n_alkane_dD_permil | M1: LeafWater_dD_permil | N1: XylemWater_dD_permil | O1: EnvironmentalWater_dD_permil | P1: Eps_C27_vs_Xylem_permil | Q1: Eps_C29_vs_Xylem_permil | R1: Eps_C31_vs_Xylem_permil | S1: Eps_C27_vs_LeafWater_permil | T1: Eps_C29_vs_LeafWater_permil | U1: Eps_C31_vs_LeafWater_permil | V1: Eps_C27_vs_EnvWater_permil | W1: Eps_C29_vs_EnvWater_permil | X1: Eps_C31_vs_EnvWater_permil | Y1: C29_minus_C27_permil | Z1: C31_minus_C29_permil | AA1: DOI | AB1: Source_URL | AC1: Supplement_URL
A2: Gao2014 | B2: sp1 | C2: Lycop | D2: Selaginella moellendorffii | E2: F/H | F2: -141 | G2: -137 | J2: -117 | K2: -129 | O2: -57 | P2: =IF(OR(J2="",N2=""),"",1000*((1+J2/1000)/(1+N2/1000)-1)) | Q2: =IF(OR(K2="",N2=""),"",1000*((1+K2/1000)/(1+N2/1000)-1)) | R2: =IF(OR(L2="",N2=""),"",1000*((1+L2/1000)/(1+N2/1000)-1)) | S2: =IF(OR(J2="",M2=""),"",1000*((1+J2/1000)/(1+M2/1000)-1)) | T2: =IF(OR(K2="",M2=""),"",1000*((1+K2/1000)/(1+M2/1000)-1)) | U2: =IF(OR(L2="",M2=""),"",1000*((1+L2/1000)/(1+M2/1000)-1)) | V2: =IF(J2="","",1000*((1+J2/1000)/(1+O2/1000)-1)) -> -63.626723 | W2: =IF(K2="","",1000*((1+K2/1000)/(1+O2/1000)-1)) -> -76.352068 | X2: =IF(L2="","",1000*((1+L2/1000)/(1+O2/1000)-1)) | Y2: =IF(OR(J2="",K2=""),"",K2-J2) -> -12 | Z2: =IF(OR(K2="",L2=""),"",L2-K2) | AA2: 10.1371/journal.pone.0112610 | AB2: https://journals.plos.org/plosone/article?id=10.1371/journal.pone.0112610 | AC2: https://doi.org/10.1371/journal.pone.0112610.s008
A3: Gao2014 | B3: sp2 | C3: Lycop | D3: Selaginella huehuetenangensis | E3: F/H | F3: -132 | G3: -121 | H3: -131 | J3: -119 | K3: -133 | L3: -109 | O3: -57 | P3: =IF(OR(J3="",N3=""),"",1000*((1+J3/1000)/(1+N3/1000)-1)) | Q3: =IF(OR(K3="",N3=""),"",1000*((1+K3/1000)/(1+N3/1000)-1)) | R3: =IF(OR(L3="",N3=""),"",1000*((1+L3/1000)/(1+N3/1000)-1)) | S3: =IF(OR(J3="",M3=""),"",1000*((1+J3/1000)/(1+M3/1000)-1)) | T3: =IF(OR(K3="",M3=""),"",1000*((1+K3/1000)/(1+M3/1000)-1)) | U3: =IF(OR(L3="",M3=""),"",1000*((1+L3/1000)/(1+M3/1000)-1)) | V3: =IF(J3="","",1000*((1+J3/1000)/(1+O3/1000)-1)) -> -65.747614 | W3: =IF(K3="","",1000*((1+K3/1000)/(1+O3/1000)-1)) -> -80.593849 | X3: =IF(L3="","",1000*((1+L3/1000)/(1+O3/1000)-1)) -> -55.14316 | Y3: =IF(OR(J3="",K3=""),"",K3-J3) -> -14 | Z3: =IF(OR(K3="",L3=""),"",L3-K3) -> 24 | AA3: 10.1371/journal.pone.0112610 | AB3: https://journals.plos.org/plosone/article?id=10.1371/journal.pone.0112610 | AC3: https://doi.org/10.1371/journal.pone.0112610.s008
A4: Gao2014 | B4: sp3 | C4: Lycop | D4: Selaginella schiedeana | E4: F/H | F4: -125 | G4: -134 | H4: -129 | I4: -124 | J4: -129 | K4: -118 | O4: -57 | P4: =IF(OR(J4="",N4=""),"",1000*((1+J4/1000)/(1+N4/1000)-1)) | Q4: =IF(OR(K4="",N4=""),"",1000*((1+K4/1000)/(1+N4/1000)-1)) | R4: =IF(OR(L4="",N4=""),"",1000*((1+L4/1000)/(1+N4/1000)-1)) | S4: =IF(OR(J4="",M4=""),"",1000*((1+J4/1000)/(1+M4/1000)-1)) | T4: =IF(OR(K4="",M4=""),"",1000*((1+K4/1000)/(1+M4/1000)-1)) | U4: =IF(OR(L4="",M4=""),"",1000*((1+L4/1000)/(1+M4/1000)-1)) | V4: =IF(J4="","",1000*((1+J4/1000)/(1+O4/1000)-1)) -> -76.352068 | W4: =IF(K4="","",1000*((1+K4/1000)/(1+O4/1000)-1)) -> -64.687169 | X4: =IF(L4="","",1000*((1+L4/1000)/(1+O4/1000)-1)) | Y4: =IF(OR(J4="",K4=""),"",K4-J4) -> 11 | Z4: =IF(OR(K4="",L4=""),"",L4-K4) | AA4: 10.1371/journal.pone.0112610 | AB4: https://journals.plos.org/plosone/article?id=10.1371/journal.pone.0112610 | AC4: https://doi.org/10.1371/journal.pone.0112610.s008
A5: Gao2014 | B5: sp4 | C5: Lycop | D5: Selaginella kraussiana | E5: F/H | F5: -192 | G5: -189 | H5: -182 | I5: -193 | J5: -200 | K5: -172 | O5: -57 | P5: =IF(OR(J5="",N5=""),"",1000*((1+J5/1000)/(1+N5/1000)-1)) | Q5: =IF(OR(K5="",N5=""),"",1000*((1+K5/1000)/(1+N5/1000)-1)) | R5: =IF(OR(L5="",N5=""),"",1000*((1+L5/1000)/(1+N5/1000)-1)) | S5: =IF(OR(J5="",M5=""),"",1000*((1+J5/1000)/(1+M5/1000)-1)) | T5: =IF(OR(K5="",M5=""),"",1000*((1+K5/1000)/(1+M5/1000)-1)) | U5: =IF(OR(L5="",M5=""),"",1000*((1+L5/1000)/(1+M5/1000)-1)) | V5: =IF(J5="","",1000*((1+J5/1000)/(1+O5/1000)-1)) -> -151.64369 | W5: =IF(K5="","",1000*((1+K5/1000)/(1+O5/1000)-1)) -> -121.95122 | X5: =IF(L5="","",1000*((1+L5/1000)/(1+O5/1000)-1)) | Y5: =IF(OR(J5="",K5=""),"",K5-J5) -> 28 | Z5: =IF(OR(K5="",L5=""),"",L5-K5) | AA5: 10.1371/journal.pone.0112610 | AB5: https://journals.plos.org/plosone/article?id=10.1371/journal.pone.0112610 | AC5: https://doi.org/10.1371/journal.pone.0112610.s008
A6: Gao2014 | B6: sp5 | C6: Lycop | D6: Huperzia squarrosa | E6: F/H | F6: -129 | G6: -132 | H6: -113 | J6: -126 | K6: -129 | O6: -57 | P6: =IF(OR(J6="",N6=""),"",1000*((1+J6/1000)/(1+N6/1000)-1)) | Q6: =IF(OR(K6="",N6=""),"",1000*((1+K6/1000)/(1+N6/1000)-1)) | R6: =IF(OR(L6="",N6=""),"",1000*((1+L6/1000)/(1+N6/1000)-1)) | S6: =IF(OR(J6="",M6=""),"",1000*((1+J6/1000)/(1+M6/1000)-1)) | T6: =IF(OR(K6="",M6=""),"",1000*((1+K6/1000)/(1+M6/1000)-1)) | U6: =IF(OR(L6="",M6=""),"",1000*((1+L6/1000)/(1+M6/1000)-1)) | V6: =IF(J6="","",1000*((1+J6/1000)/(1+O6/1000)-1)) -> -73.170732 | W6: =IF(K6="","",1000*((1+K6/1000)/(1+O6/1000)-1)) -> -76.352068 | X6: =IF(L6="","",1000*((1+L6/1000)/(1+O6/1000)-1)) | Y6: =IF(OR(J6="",K6=""),"",K6-J6) -> -3 | Z6: =IF(OR(K6="",L6=""),"",L6-K6) | AA6: 10.1371/journal.pone.0112610 | AB6: https://journals.plos.org/plosone/article?id=10.1371/journal.pone.0112610 | AC6: https://doi.org/10.1371/journal.pone.0112610.s008
A7: Gao2014 | B7: sp6 | C7: Lycop | D7: Huperzia sp. | E7: F/H | F7: -124 | G7: -122 | H7: -98 | J7: -98 | K7: -112 | O7: -57 | P7: =IF(OR(J7="",N7=""),"",1000*((1+J7/1000)/(1+N7/1000)-1)) | Q7: =IF(OR(K7="",N7=""),"",1000*((1+K7/1000)/(1+N7/1000)-1)) | R7: =IF(OR(L7="",N7=""),"",1000*((1+L7/1000)/(1+N7/1000)-1)) | S7: =IF(OR(J7="",M7=""),"",1000*((1+J7/1000)/(1+M7/1000)-1)) | T7: =IF(OR(K7="",M7=""),"",1000*((1+K7/1000)/(1+M7/1000)-1)) | U7: =IF(OR(L7="",M7=""),"",1000*((1+L7/1000)/(1+M7/1000)-1)) | V7: =IF(J7="","",1000*((1+J7/1000)/(1+O7/1000)-1)) -> -43.478261 | W7: =IF(K7="","",1000*((1+K7/1000)/(1+O7/1000)-1)) -> -58.324496 | X7: =IF(L7="","",1000*((1+L7/1000)/(1+O7/1000)-1)) | Y7: =IF(OR(J7="",K7=""),"",K7-J7) -> -14 | Z7: =IF(OR(K7="",L7=""),"",L7-K7) | AA7: 10.1371/journal.pone.0112610 | AB7: https://journals.plos.org/plosone/article?id=10.1371/journal.pone.0112610 | AC7: https://doi.org/10.1371/journal.pone.0112610.s008
A8: Gao2014 | B8: sp7 | C8: Lycop | D8: Selaginella mosorongensis | E8: F/H | F8: -137 | G8: -139 | H8: -143 | I8: -175 | J8: -139 | K8: -170 | L8: -182 | O8: -57 | P8: =IF(OR(J8="",N8=""),"",1000*((1+J8/1000)/(1+N8/1000)-1)) | Q8: =IF(OR(K8="",N8=""),"",1000*((1+K8/1000)/(1+N8/1000)-1)) | R8: =IF(OR(L8="",N8=""),"",1000*((1+L8/1000)/(1+N8/1000)-1)) | S8: =IF(OR(J8="",M8=""),"",1000*((1+J8/1000)/(1+M8/1000)-1)) | T8: =IF(OR(K8="",M8=""),"",1000*((1+K8/1000)/(1+M8/1000)-1)) | U8: =IF(OR(L8="",M8=""),"",1000*((1+L8/1000)/(1+M8/1000)-1)) | V8: =IF(J8="","",1000*((1+J8/1000)/(1+O8/1000)-1)) -> -86.956522 | W8: =IF(K8="","",1000*((1+K8/1000)/(1+O8/1000)-1)) -> -119.83033 | X8: =IF(L8="","",1000*((1+L8/1000)/(1+O8/1000)-1)) -> -132.55567 | Y8: =IF(OR(J8="",K8=""),"",K8-J8) -> -31 | Z8: =IF(OR(K8="",L8=""),"",L8-K8) -> -12 | AA8: 10.1371/journal.pone.0112610 | AB8: https://journals.plos.org/plosone/article?id=10.1371/journal.pone.0112610 | AC8: https://doi.org/10.1371/journal.pone.0112610.s008
A9: Gao2014 | B9: sp8 | C9: Lycop | D9: Selaginella mickelii | E9: F/H | F9: -132 | G9: -129 | H9: -127 | I9: -96 | J9: -126 | K9: -137 | L9: -117 | O9: -57 | P9: =IF(OR(J9="",N9=""),"",1000*((1+J9/1000)/(1+N9/1000)-1)) | Q9: =IF(OR(K9="",N9=""),"",1000*((1+K9/1000)/(1+N9/1000)-1)) | R9: =IF(OR(L9="",N9=""),"",1000*((1+L9/1000)/(1+N9/1000)-1)) | S9: =IF(OR(J9="",M9=""),"",1000*((1+J9/1000)/(1+M9/1000)-1)) | T9: =IF(OR(K9="",M9=""),"",1000*((1+K9/1000)/(1+M9/1000)-1)) | U9: =IF(OR(L9="",M9=""),"",1000*((1+L9/1000)/(1+M9/1000)-1)) | V9: =IF(J9="","",1000*((1+J9/1000)/(1+O9/1000)-1)) -> -73.170732 | W9: =IF(K9="","",1000*((1+K9/1000)/(1+O9/1000)-1)) -> -84.835631 | X9: =IF(L9="","",1000*((1+L9/1000)/(1+O9/1000)-1)) -> -63.626723 | Y9: =IF(OR(J9="",K9=""),"",K9-J9) -> -11 | Z9: =IF(OR(K9="",L9=""),"",L9-K9) -> 20 | AA9: 10.1371/journal.pone.0112610 | AB9: https://journals.plos.org/plosone/article?id=10.1371/journal.pone.0112610 | AC9: https://doi.org/10.1371/journal.pone.0112610.s008
A10: Gao2014 | B10: sp9 | C10: Lycop | D10: Selaginella galeottii | E10: F/H | J10: -101 | O10: -57 | P10: =IF(OR(J10="",N10=""),"",1000*((1+J10/1000)/(1+N10/1000)-1)) | Q10: =IF(OR(K10="",N10=""),"",1000*((1+K10/1000)/(1+N10/1000)-1)) | R10: =IF(OR(L10="",N10=""),"",1000*((1+L10/1000)/(1+N10/1000)-1)) | S10: =IF(OR(J10="",M10=""),"",1000*((1+J10/1000)/(1+M10/1000)-1)) | T10: =IF(OR(K10="",M10=""),"",1000*((1+K10/1000)/(1+M10/1000)-1)) | U10: =IF(OR(L10="",M10=""),"",1000*((1+L10/1000)/(1+M10/1000)-1)) | V10: =IF(J10="","",1000*((1+J10/1000)/(1+O10/1000)-1)) -> -46.659597 | W10: =IF(K10="","",1000*((1+K10/1000)/(1+O10/1000)-1)) | X10: =IF(L10="","",1000*((1+L10/1000)/(1+O10/1000)-1)) | Y10: =IF(OR(J10="",K10=""),"",K10-J10) | Z10: =IF(OR(K10="",L10=""),"",L10-K10) | AA10: 10.1371/journal.pone.0112610 | AB10: https://journals.plos.org/plosone/article?id=10.1371/journal.pone.0112610 | AC10: https://doi.org/10.1371/journal.pone.0112610.s008
A11: Gao2014 | B11: sp10 | C11: Lycop | D11: Selaginella brauniii | E11: F/H | F11: -177 | G11: -179 | H11: -175 | J11: -139 | K11: -139 | O11: -57 | P11: =IF(OR(J11="",N11=""),"",1000*((1+J11/1000)/(1+N11/1000)-1)) | Q11: =IF(OR(K11="",N11=""),"",1000*((1+K11/1000)/(1+N11/1000)-1)) | R11: =IF(OR(L11="",N11=""),"",1000*((1+L11/1000)/(1+N11/1000)-1)) | S11: =IF(OR(J11="",M11=""),"",1000*((1+J11/1000)/(1+M11/1000)-1)) | T11: =IF(OR(K11="",M11=""),"",1000*((1+K11/1000)/(1+M11/1000)-1)) | U11: =IF(OR(L11="",M11=""),"",1000*((1+L11/1000)/(1+M11/1000)-1)) | V11: =IF(J11="","",1000*((1+J11/1000)/(1+O11/1000)-1)) -> -86.956522 | W11: =IF(K11="","",1000*((1+K11/1000)/(1+O11/1000)-1)) -> -86.956522 | X11: =IF(L11="","",1000*((1+L11/1000)/(1+O11/1000)-1)) | Y11: =IF(OR(J11="",K11=""),"",K11-J11) -> 0 | Z11: =IF(OR(K11="",L11=""),"",L11-K11) | AA11: 10.1371/journal.pone.0112610 | AB11: https://journals.plos.org/plosone/article?id=10.1371/journal.pone.0112610 | AC11: https://doi.org/10.1371/journal.pone.0112610.s008
A12: Gao2014 | B12: sp11 | C12: Fern | D12: Dicksonia antartica | E12: Tree | F12: -171 | G12: -155 | H12: -147 | I12: -141 | K12: -143 | L12: -164 | M12: -17.6 | N12: -44 | O12: -57 | P12: =IF(OR(J12="",N12=""),"",1000*((1+J12/1000)/(1+N12/1000)-1)) | Q12: =IF(OR(K12="",N12=""),"",1000*((1+K12/1000)/(1+N12/1000)-1)) -> -103.55649 | R12: =IF(OR(L12="",N12=""),"",1000*((1+L12/1000)/(1+N12/1000)-1)) -> -125.52301 | S12: =IF(OR(J12="",M12=""),"",1000*((1+J12/1000)/(1+M12/1000)-1)) | T12: =IF(OR(K12="",M12=""),"",1000*((1+K12/1000)/(1+M12/1000)-1)) -> -127.64658 | U12: =IF(OR(L12="",M12=""),"",1000*((1+L12/1000)/(1+M12/1000)-1)) -> -149.0228 | V12: =IF(J12="","",1000*((1+J12/1000)/(1+O12/1000)-1)) | W12: =IF(K12="","",1000*((1+K12/1000)/(1+O12/1000)-1)) -> -91.198303 | X12: =IF(L12="","",1000*((1+L12/1000)/(1+O12/1000)-1)) -> -113.46766 | Y12: =IF(OR(J12="",K12=""),"",K12-J12) | Z12: =IF(OR(K12="",L12=""),"",L12-K12) -> -21 | AA12: 10.1371/journal.pone.0112610 | AB12: https://journals.plos.org/plosone/article?id=10.1371/journal.pone.0112610 | AC12: https://doi.org/10.1371/journal.pone.0112610.s008
A13: Gao2014 | B13: sp12 | C13: Fern | D13: Alsophila firma | E13: Tree | F13: -111 | G13: -117 | H13: -148 | I13: -124 | J13: -110 | K13: -116 | L13: -114 | M13: -1.9 | N13: -49.9 | O13: -57 | P13: =IF(OR(J13="",N13=""),"",1000*((1+J13/1000)/(1+N13/1000)-1)) -> -63.256499 | Q13: =IF(OR(K13="",N13=""),"",1000*((1+K13/1000)/(1+N13/1000)-1)) -> -69.571624 | R13: =IF(OR(L13="",N13=""),"",1000*((1+L13/1000)/(1+N13/1000)-1)) -> -67.466582 | S13: =IF(OR(J13="",M13=""),"",1000*((1+J13/1000)/(1+M13/1000)-1)) -> -108.30578 | T13: =IF(OR(K13="",M13=""),"",1000*((1+K13/1000)/(1+M13/1000)-1)) -> -114.3172 | U13: =IF(OR(L13="",M13=""),"",1000*((1+L13/1000)/(1+M13/1000)-1)) -> -112.3134 | V13: =IF(J13="","",1000*((1+J13/1000)/(1+O13/1000)-1)) -> -56.203606 | W13: =IF(K13="","",1000*((1+K13/1000)/(1+O13/1000)-1)) -> -62.566278 | X13: =IF(L13="","",1000*((1+L13/1000)/(1+O13/1000)-1)) -> -60.445387 | Y13: =IF(OR(J13="",K13=""),"",K13-J13) -> -6 | Z13: =IF(OR(K13="",L13=""),"",L13-K13) -> 2 | AA13: 10.1371/journal.pone.0112610 | AB13: https://journals.plos.org/plosone/article?id=10.1371/journal.pone.0112610 | AC13: https://doi.org/10.1371/journal.pone.0112610.s008
A14: Gao2014 | B14: sp13 | C14: Fern | D14: Matteuccia struthiopteris | E14: F/H | F14: -123 | G14: -127 | H14: -129 | I14: -117 | J14: -128 | K14: -127 | L14: -160 | M14: -3.7 | N14: -34.7 | O14: -57 | P14: =IF(OR(J14="",N14=""),"",1000*((1+J14/1000)/(1+N14/1000)-1)) -> -96.65389 | Q14: =IF(OR(K14="",N14=""),"",1000*((1+K14/1000)/(1+N14/1000)-1)) -> -95.617943 | R14: =IF(OR(L14="",N14=""),"",1000*((1+L14/1000)/(1+N14/1000)-1)) -> -129.80421 | S14: =IF(OR(J14="",M14=""),"",1000*((1+J14/1000)/(1+M14/1000)-1)) -> -124.76162 | T14: =IF(OR(K14="",M14=""),"",1000*((1+K14/1000)/(1+M14/1000)-1)) -> -123.7579 | U14: =IF(OR(L14="",M14=""),"",1000*((1+L14/1000)/(1+M14/1000)-1)) -> -156.88046 | V14: =IF(J14="","",1000*((1+J14/1000)/(1+O14/1000)-1)) -> -75.291622 | W14: =IF(K14="","",1000*((1+K14/1000)/(1+O14/1000)-1)) -> -74.231177 | X14: =IF(L14="","",1000*((1+L14/1000)/(1+O14/1000)-1)) -> -109.22587 | Y14: =IF(OR(J14="",K14=""),"",K14-J14) -> 1 | Z14: =IF(OR(K14="",L14=""),"",L14-K14) -> -33 | AA14: 10.1371/journal.pone.0112610 | AB14: https://journals.plos.org/plosone/article?id=10.1371/journal.pone.0112610 | AC14: https://doi.org/10.1371/journal.pone.0112610.s008
A15: Gao2014 | B15: sp14 | C15: Fern | D15: Adiantum pedatum | E15: F/H | F15: -111 | G15: -119 | H15: -113 | J15: -118 | K15: -182 | M15: -17.5 | N15: -38.8 | O15: -57 | P15: =IF(OR(J15="",N15=""),"",1000*((1+J15/1000)/(1+N15/1000)-1)) -> -82.397004 | Q15: =IF(OR(K15="",N15=""),"",1000*((1+K15/1000)/(1+N15/1000)-1)) -> -148.98044 | R15: =IF(OR(L15="",N15=""),"",1000*((1+L15/1000)/(1+N15/1000)-1)) | S15: =IF(OR(J15="",M15=""),"",1000*((1+J15/1000)/(1+M15/1000)-1)) -> -102.29008 | T15: =IF(OR(K15="",M15=""),"",1000*((1+K15/1000)/(1+M15/1000)-1)) -> -167.43003 | U15: =IF(OR(L15="",M15=""),"",1000*((1+L15/1000)/(1+M15/1000)-1)) | V15: =IF(J15="","",1000*((1+J15/1000)/(1+O15/1000)-1)) -> -64.687169 | W15: =IF(K15="","",1000*((1+K15/1000)/(1+O15/1000)-1)) -> -132.55567 | X15: =IF(L15="","",1000*((1+L15/1000)/(1+O15/1000)-1)) | Y15: =IF(OR(J15="",K15=""),"",K15-J15) -> -64 | Z15: =IF(OR(K15="",L15=""),"",L15-K15) | AA15: 10.1371/journal.pone.0112610 | AB15: https://journals.plos.org/plosone/article?id=10.1371/journal.pone.0112610 | AC15: https://doi.org/10.1371/journal.pone.0112610.s008
A16: Gao2014 | B16: sp15 | C16: Fern* | D16: Marattia attenuata | E16: F/H | F16: -155 | G16: -168 | H16: -203 | I16: -164 | O16: -57 | P16: =IF(OR(J16="",N16=""),"",1000*((1+J16/1000)/(1+N16/1000)-1)) | Q16: =IF(OR(K16="",N16=""),"",1000*((1+K16/1000)/(1+N16/1000)-1)) | R16: =IF(OR(L16="",N16=""),"",1000*((1+L16/1000)/(1+N16/1000)-1)) | S16: =IF(OR(J16="",M16=""),"",1000*((1+J16/1000)/(1+M16/1000)-1)) | T16: =IF(OR(K16="",M16=""),"",1000*((1+K16/1000)/(1+M16/1000)-1)) | U16: =IF(OR(L16="",M16=""),"",1000*((1+L16/1000)/(1+M16/1000)-1)) | V16: =IF(J16="","",1000*((1+J16/1000)/(1+O16/1000)-1)) | W16: =IF(K16="","",1000*((1+K16/1000)/(1+O16/1000)-1)) | X16: =IF(L16="","",1000*((1+L16/1000)/(1+O16/1000)-1)) | Y16: =IF(OR(J16="",K16=""),"",K16-J16) | Z16: =IF(OR(K16="",L16=""),"",L16-K16) | AA16: 10.1371/journal.pone.0112610 | AB16: https://journals.plos.org/plosone/article?id=10.1371/journal.pone.0112610 | AC16: https://doi.org/10.1371/journal.pone.0112610.s008
A17: Gao2014 | B17: sp16 | C17: Fern* | D17: Dennstaedtia globulifera | E17: F/H | F17: -140 | G17: -150 | H17: -148 | I17: -156 | J17: -111 | K17: -136 | O17: -57 | P17: =IF(OR(J17="",N17=""),"",1000*((1+J17/1000)/(1+N17/1000)-1)) | Q17: =IF(OR(K17="",N17=""),"",1000*((1+K17/1000)/(1+N17/1000)-1)) | R17: =IF(OR(L17="",N17=""),"",1000*((1+L17/1000)/(1+N17/1000)-1)) | S17: =IF(OR(J17="",M17=""),"",1000*((1+J17/1000)/(1+M17/1000)-1)) | T17: =IF(OR(K17="",M17=""),"",1000*((1+K17/1000)/(1+M17/1000)-1)) | U17: =IF(OR(L17="",M17=""),"",1000*((1+L17/1000)/(1+M17/1000)-1)) | V17: =IF(J17="","",1000*((1+J17/1000)/(1+O17/1000)-1)) -> -57.264051 | W17: =IF(K17="","",1000*((1+K17/1000)/(1+O17/1000)-1)) -> -83.775186 | X17: =IF(L17="","",1000*((1+L17/1000)/(1+O17/1000)-1)) | Y17: =IF(OR(J17="",K17=""),"",K17-J17) -> -25 | Z17: =IF(OR(K17="",L17=""),"",L17-K17) | AA17: 10.1371/journal.pone.0112610 | AB17: https://journals.plos.org/plosone/article?id=10.1371/journal.pone.0112610 | AC17: https://doi.org/10.1371/journal.pone.0112610.s008
A18: Gao2014 | B18: sp17 | C18: Fern* | D18: Asplenium formosanum | E18: F/H | F18: -184 | G18: -186 | H18: -183 | I18: -182 | K18: -177 | L18: -174 | O18: -57 | P18: =IF(OR(J18="",N18=""),"",1000*((1+J18/1000)/(1+N18/1000)-1)) | Q18: =IF(OR(K18="",N18=""),"",1000*((1+K18/1000)/(1+N18/1000)-1)) | R18: =IF(OR(L18="",N18=""),"",1000*((1+L18/1000)/(1+N18/1000)-1)) | S18: =IF(OR(J18="",M18=""),"",1000*((1+J18/1000)/(1+M18/1000)-1)) | T18: =IF(OR(K18="",M18=""),"",1000*((1+K18/1000)/(1+M18/1000)-1)) | U18: =IF(OR(L18="",M18=""),"",1000*((1+L18/1000)/(1+M18/1000)-1)) | V18: =IF(J18="","",1000*((1+J18/1000)/(1+O18/1000)-1)) | W18: =IF(K18="","",1000*((1+K18/1000)/(1+O18/1000)-1)) -> -127.25345 | X18: =IF(L18="","",1000*((1+L18/1000)/(1+O18/1000)-1)) -> -124.07211 | Y18: =IF(OR(J18="",K18=""),"",K18-J18) | Z18: =IF(OR(K18="",L18=""),"",L18-K18) -> 3 | AA18: 10.1371/journal.pone.0112610 | AB18: https://journals.plos.org/plosone/article?id=10.1371/journal.pone.0112610 | AC18: https://doi.org/10.1371/journal.pone.0112610.s008
A19: Gao2014 | B19: sp18 | C19: Fern* | D19: Thelypteris sp. | E19: F/H | F19: -130 | G19: -127 | H19: -133 | I19: -140 | J19: -118 | K19: -133 | L19: -137 | O19: -57 | P19: =IF(OR(J19="",N19=""),"",1000*((1+J19/1000)/(1+N19/1000)-1)) | Q19: =IF(OR(K19="",N19=""),"",1000*((1+K19/1000)/(1+N19/1000)-1)) | R19: =IF(OR(L19="",N19=""),"",1000*((1+L19/1000)/(1+N19/1000)-1)) | S19: =IF(OR(J19="",M19=""),"",1000*((1+J19/1000)/(1+M19/1000)-1)) | T19: =IF(OR(K19="",M19=""),"",1000*((1+K19/1000)/(1+M19/1000)-1)) | U19: =IF(OR(L19="",M19=""),"",1000*((1+L19/1000)/(1+M19/1000)-1)) | V19: =IF(J19="","",1000*((1+J19/1000)/(1+O19/1000)-1)) -> -64.687169 | W19: =IF(K19="","",1000*((1+K19/1000)/(1+O19/1000)-1)) -> -80.593849 | X19: =IF(L19="","",1000*((1+L19/1000)/(1+O19/1000)-1)) -> -84.835631 | Y19: =IF(OR(J19="",K19=""),"",K19-J19) -> -15 | Z19: =IF(OR(K19="",L19=""),"",L19-K19) -> -4 | AA19: 10.1371/journal.pone.0112610 | AB19: https://journals.plos.org/plosone/article?id=10.1371/journal.pone.0112610 | AC19: https://doi.org/10.1371/journal.pone.0112610.s008
A20: Gao2014 | B20: sp19 | C20: Fern* | D20: Blechnum glandulosum | E20: F/H | F20: -147 | G20: -145 | H20: -142 | I20: -149 | J20: -124 | K20: -136 | O20: -57 | P20: =IF(OR(J20="",N20=""),"",1000*((1+J20/1000)/(1+N20/1000)-1)) | Q20: =IF(OR(K20="",N20=""),"",1000*((1+K20/1000)/(1+N20/1000)-1)) | R20: =IF(OR(L20="",N20=""),"",1000*((1+L20/1000)/(1+N20/1000)-1)) | S20: =IF(OR(J20="",M20=""),"",1000*((1+J20/1000)/(1+M20/1000)-1)) | T20: =IF(OR(K20="",M20=""),"",1000*((1+K20/1000)/(1+M20/1000)-1)) | U20: =IF(OR(L20="",M20=""),"",1000*((1+L20/1000)/(1+M20/1000)-1)) | V20: =IF(J20="","",1000*((1+J20/1000)/(1+O20/1000)-1)) -> -71.049841 | W20: =IF(K20="","",1000*((1+K20/1000)/(1+O20/1000)-1)) -> -83.775186 | X20: =IF(L20="","",1000*((1+L20/1000)/(1+O20/1000)-1)) | Y20: =IF(OR(J20="",K20=""),"",K20-J20) -> -12 | Z20: =IF(OR(K20="",L20=""),"",L20-K20) | AA20: 10.1371/journal.pone.0112610 | AB20: https://journals.plos.org/plosone/article?id=10.1371/journal.pone.0112610 | AC20: https://doi.org/10.1371/journal.pone.0112610.s008
A21: Gao2014 | B21: sp20 | C21: Fern* | D21: Arachniodes amabilis | E21: F/H | F21: -164 | G21: -163 | H21: -163 | I21: -172 | J21: -140 | K21: -149 | L21: -165 | O21: -57 | P21: =IF(OR(J21="",N21=""),"",1000*((1+J21/1000)/(1+N21/1000)-1)) | Q21: =IF(OR(K21="",N21=""),"",1000*((1+K21/1000)/(1+N21/1000)-1)) | R21: =IF(OR(L21="",N21=""),"",1000*((1+L21/1000)/(1+N21/1000)-1)) | S21: =IF(OR(J21="",M21=""),"",1000*((1+J21/1000)/(1+M21/1000)-1)) | T21: =IF(OR(K21="",M21=""),"",1000*((1+K21/1000)/(1+M21/1000)-1)) | U21: =IF(OR(L21="",M21=""),"",1000*((1+L21/1000)/(1+M21/1000)-1)) | V21: =IF(J21="","",1000*((1+J21/1000)/(1+O21/1000)-1)) -> -88.016967 | W21: =IF(K21="","",1000*((1+K21/1000)/(1+O21/1000)-1)) -> -97.560976 | X21: =IF(L21="","",1000*((1+L21/1000)/(1+O21/1000)-1)) -> -114.5281 | Y21: =IF(OR(J21="",K21=""),"",K21-J21) -> -9 | Z21: =IF(OR(K21="",L21=""),"",L21-K21) -> -16 | AA21: 10.1371/journal.pone.0112610 | AB21: https://journals.plos.org/plosone/article?id=10.1371/journal.pone.0112610 | AC21: https://doi.org/10.1371/journal.pone.0112610.s008
A22: Gao2014 | B22: sp21 | C22: Fern* | D22: Arthropteris articulata | E22: F/H | F22: -153 | G22: -125 | H22: -143 | I22: -131 | K22: -151 | L22: -153 | O22: -57 | P22: =IF(OR(J22="",N22=""),"",1000*((1+J22/1000)/(1+N22/1000)-1)) | Q22: =IF(OR(K22="",N22=""),"",1000*((1+K22/1000)/(1+N22/1000)-1)) | R22: =IF(OR(L22="",N22=""),"",1000*((1+L22/1000)/(1+N22/1000)-1)) | S22: =IF(OR(J22="",M22=""),"",1000*((1+J22/1000)/(1+M22/1000)-1)) | T22: =IF(OR(K22="",M22=""),"",1000*((1+K22/1000)/(1+M22/1000)-1)) | U22: =IF(OR(L22="",M22=""),"",1000*((1+L22/1000)/(1+M22/1000)-1)) | V22: =IF(J22="","",1000*((1+J22/1000)/(1+O22/1000)-1)) | W22: =IF(K22="","",1000*((1+K22/1000)/(1+O22/1000)-1)) -> -99.681866 | X22: =IF(L22="","",1000*((1+L22/1000)/(1+O22/1000)-1)) -> -101.80276 | Y22: =IF(OR(J22="",K22=""),"",K22-J22) | Z22: =IF(OR(K22="",L22=""),"",L22-K22) -> -2 | AA22: 10.1371/journal.pone.0112610 | AB22: https://journals.plos.org/plosone/article?id=10.1371/journal.pone.0112610 | AC22: https://doi.org/10.1371/journal.pone.0112610.s008
A23: Gao2014 | B23: sp22 | C23: Fern* | D23: Bolbitis portoricensis | E23: F/H | F23: -140 | G23: -145 | H23: -141 | I23: -151 | L23: -157 | O23: -57 | P23: =IF(OR(J23="",N23=""),"",1000*((1+J23/1000)/(1+N23/1000)-1)) | Q23: =IF(OR(K23="",N23=""),"",1000*((1+K23/1000)/(1+N23/1000)-1)) | R23: =IF(OR(L23="",N23=""),"",1000*((1+L23/1000)/(1+N23/1000)-1)) | S23: =IF(OR(J23="",M23=""),"",1000*((1+J23/1000)/(1+M23/1000)-1)) | T23: =IF(OR(K23="",M23=""),"",1000*((1+K23/1000)/(1+M23/1000)-1)) | U23: =IF(OR(L23="",M23=""),"",1000*((1+L23/1000)/(1+M23/1000)-1)) | V23: =IF(J23="","",1000*((1+J23/1000)/(1+O23/1000)-1)) | W23: =IF(K23="","",1000*((1+K23/1000)/(1+O23/1000)-1)) | X23: =IF(L23="","",1000*((1+L23/1000)/(1+O23/1000)-1)) -> -106.04454 | Y23: =IF(OR(J23="",K23=""),"",K23-J23) | Z23: =IF(OR(K23="",L23=""),"",L23-K23) | AA23: 10.1371/journal.pone.0112610 | AB23: https://journals.plos.org/plosone/article?id=10.1371/journal.pone.0112610 | AC23: https://doi.org/10.1371/journal.pone.0112610.s008
A24: Gao2014 | B24: sp23 | C24: Fern* | D24: Campyloneurum angustifolium | E24: F/H | F24: -133 | G24: -134 | H24: -142 | I24: -136 | J24: -120 | K24: -137 | L24: -133 | O24: -57 | P24: =IF(OR(J24="",N24=""),"",1000*((1+J24/1000)/(1+N24/1000)-1)) | Q24: =IF(OR(K24="",N24=""),"",1000*((1+K24/1000)/(1+N24/1000)-1)) | R24: =IF(OR(L24="",N24=""),"",1000*((1+L24/1000)/(1+N24/1000)-1)) | S24: =IF(OR(J24="",M24=""),"",1000*((1+J24/1000)/(1+M24/1000)-1)) | T24: =IF(OR(K24="",M24=""),"",1000*((1+K24/1000)/(1+M24/1000)-1)) | U24: =IF(OR(L24="",M24=""),"",1000*((1+L24/1000)/(1+M24/1000)-1)) | V24: =IF(J24="","",1000*((1+J24/1000)/(1+O24/1000)-1)) -> -66.808059 | W24: =IF(K24="","",1000*((1+K24/1000)/(1+O24/1000)-1)) -> -84.835631 | X24: =IF(L24="","",1000*((1+L24/1000)/(1+O24/1000)-1)) -> -80.593849 | Y24: =IF(OR(J24="",K24=""),"",K24-J24) -> -17 | Z24: =IF(OR(K24="",L24=""),"",L24-K24) -> 4 | AA24: 10.1371/journal.pone.0112610 | AB24: https://journals.plos.org/plosone/article?id=10.1371/journal.pone.0112610 | AC24: https://doi.org/10.1371/journal.pone.0112610.s008
A25: Gao2014 | B25: sp24 | C25: Fern* | D25: Tectaria zeylanica | E25: F/H | F25: -160 | G25: -160 | H25: -159 | I25: -165 | J25: -148 | K25: -153 | L25: -161 | O25: -57 | P25: =IF(OR(J25="",N25=""),"",1000*((1+J25/1000)/(1+N25/1000)-1)) | Q25: =IF(OR(K25="",N25=""),"",1000*((1+K25/1000)/(1+N25/1000)-1)) | R25: =IF(OR(L25="",N25=""),"",1000*((1+L25/1000)/(1+N25/1000)-1)) | S25: =IF(OR(J25="",M25=""),"",1000*((1+J25/1000)/(1+M25/1000)-1)) | T25: =IF(OR(K25="",M25=""),"",1000*((1+K25/1000)/(1+M25/1000)-1)) | U25: =IF(OR(L25="",M25=""),"",1000*((1+L25/1000)/(1+M25/1000)-1)) | V25: =IF(J25="","",1000*((1+J25/1000)/(1+O25/1000)-1)) -> -96.50053 | W25: =IF(K25="","",1000*((1+K25/1000)/(1+O25/1000)-1)) -> -101.80276 | X25: =IF(L25="","",1000*((1+L25/1000)/(1+O25/1000)-1)) -> -110.28632 | Y25: =IF(OR(J25="",K25=""),"",K25-J25) -> -5 | Z25: =IF(OR(K25="",L25=""),"",L25-K25) -> -8 | AA25: 10.1371/journal.pone.0112610 | AB25: https://journals.plos.org/plosone/article?id=10.1371/journal.pone.0112610 | AC25: https://doi.org/10.1371/journal.pone.0112610.s008
A26: Gao2014 | B26: sp25 | C26: Fern* | D26: Osmunda regalis | E26: F/H | F26: -148 | G26: -162 | H26: -161 | I26: -160 | J26: -171 | K26: -171 | L26: -154 | O26: -57 | P26: =IF(OR(J26="",N26=""),"",1000*((1+J26/1000)/(1+N26/1000)-1)) | Q26: =IF(OR(K26="",N26=""),"",1000*((1+K26/1000)/(1+N26/1000)-1)) | R26: =IF(OR(L26="",N26=""),"",1000*((1+L26/1000)/(1+N26/1000)-1)) | S26: =IF(OR(J26="",M26=""),"",1000*((1+J26/1000)/(1+M26/1000)-1)) | T26: =IF(OR(K26="",M26=""),"",1000*((1+K26/1000)/(1+M26/1000)-1)) | U26: =IF(OR(L26="",M26=""),"",1000*((1+L26/1000)/(1+M26/1000)-1)) | V26: =IF(J26="","",1000*((1+J26/1000)/(1+O26/1000)-1)) -> -120.89077 | W26: =IF(K26="","",1000*((1+K26/1000)/(1+O26/1000)-1)) -> -120.89077 | X26: =IF(L26="","",1000*((1+L26/1000)/(1+O26/1000)-1)) -> -102.8632 | Y26: =IF(OR(J26="",K26=""),"",K26-J26) -> 0 | Z26: =IF(OR(K26="",L26=""),"",L26-K26) -> 17 | AA26: 10.1371/journal.pone.0112610 | AB26: https://journals.plos.org/plosone/article?id=10.1371/journal.pone.0112610 | AC26: https://doi.org/10.1371/journal.pone.0112610.s008
A27: Gao2014 | B27: sp26 | C27: Fern* | D27: Osmundastrum cinnamomeum | E27: F/H | F27: -142 | G27: -145 | H27: -148 | I27: -158 | J27: -165 | K27: -160 | L27: -137 | O27: -57 | P27: =IF(OR(J27="",N27=""),"",1000*((1+J27/1000)/(1+N27/1000)-1)) | Q27: =IF(OR(K27="",N27=""),"",1000*((1+K27/1000)/(1+N27/1000)-1)) | R27: =IF(OR(L27="",N27=""),"",1000*((1+L27/1000)/(1+N27/1000)-1)) | S27: =IF(OR(J27="",M27=""),"",1000*((1+J27/1000)/(1+M27/1000)-1)) | T27: =IF(OR(K27="",M27=""),"",1000*((1+K27/1000)/(1+M27/1000)-1)) | U27: =IF(OR(L27="",M27=""),"",1000*((1+L27/1000)/(1+M27/1000)-1)) | V27: =IF(J27="","",1000*((1+J27/1000)/(1+O27/1000)-1)) -> -114.5281 | W27: =IF(K27="","",1000*((1+K27/1000)/(1+O27/1000)-1)) -> -109.22587 | X27: =IF(L27="","",1000*((1+L27/1000)/(1+O27/1000)-1)) -> -84.835631 | Y27: =IF(OR(J27="",K27=""),"",K27-J27) -> 5 | Z27: =IF(OR(K27="",L27=""),"",L27-K27) -> 23 | AA27: 10.1371/journal.pone.0112610 | AB27: https://journals.plos.org/plosone/article?id=10.1371/journal.pone.0112610 | AC27: https://doi.org/10.1371/journal.pone.0112610.s008
A28: Gao2014 | B28: sp27 | C28: Fern* | D28: Sphaeropteris horrida | E28: Tree | F28: -169 | G28: -119 | H28: -123 | I28: -140 | J28: -141 | K28: -146 | O28: -57 | P28: =IF(OR(J28="",N28=""),"",1000*((1+J28/1000)/(1+N28/1000)-1)) | Q28: =IF(OR(K28="",N28=""),"",1000*((1+K28/1000)/(1+N28/1000)-1)) | R28: =IF(OR(L28="",N28=""),"",1000*((1+L28/1000)/(1+N28/1000)-1)) | S28: =IF(OR(J28="",M28=""),"",1000*((1+J28/1000)/(1+M28/1000)-1)) | T28: =IF(OR(K28="",M28=""),"",1000*((1+K28/1000)/(1+M28/1000)-1)) | U28: =IF(OR(L28="",M28=""),"",1000*((1+L28/1000)/(1+M28/1000)-1)) | V28: =IF(J28="","",1000*((1+J28/1000)/(1+O28/1000)-1)) -> -89.077413 | W28: =IF(K28="","",1000*((1+K28/1000)/(1+O28/1000)-1)) -> -94.379639 | X28: =IF(L28="","",1000*((1+L28/1000)/(1+O28/1000)-1)) | Y28: =IF(OR(J28="",K28=""),"",K28-J28) -> -5 | Z28: =IF(OR(K28="",L28=""),"",L28-K28) | AA28: 10.1371/journal.pone.0112610 | AB28: https://journals.plos.org/plosone/article?id=10.1371/journal.pone.0112610 | AC28: https://doi.org/10.1371/journal.pone.0112610.s008
A29: Gao2014 | B29: sp28 | C29: Fern* | D29: Davallia fejeensis 'Plumosa' | E29: F/H | F29: -139 | G29: -139 | H29: -139 | I29: -141 | J29: -149 | K29: -145 | L29: -143 | O29: -57 | P29: =IF(OR(J29="",N29=""),"",1000*((1+J29/1000)/(1+N29/1000)-1)) | Q29: =IF(OR(K29="",N29=""),"",1000*((1+K29/1000)/(1+N29/1000)-1)) | R29: =IF(OR(L29="",N29=""),"",1000*((1+L29/1000)/(1+N29/1000)-1)) | S29: =IF(OR(J29="",M29=""),"",1000*((1+J29/1000)/(1+M29/1000)-1)) | T29: =IF(OR(K29="",M29=""),"",1000*((1+K29/1000)/(1+M29/1000)-1)) | U29: =IF(OR(L29="",M29=""),"",1000*((1+L29/1000)/(1+M29/1000)-1)) | V29: =IF(J29="","",1000*((1+J29/1000)/(1+O29/1000)-1)) -> -97.560976 | W29: =IF(K29="","",1000*((1+K29/1000)/(1+O29/1000)-1)) -> -93.319194 | X29: =IF(L29="","",1000*((1+L29/1000)/(1+O29/1000)-1)) -> -91.198303 | Y29: =IF(OR(J29="",K29=""),"",K29-J29) -> 4 | Z29: =IF(OR(K29="",L29=""),"",L29-K29) -> 2 | AA29: 10.1371/journal.pone.0112610 | AB29: https://journals.plos.org/plosone/article?id=10.1371/journal.pone.0112610 | AC29: https://doi.org/10.1371/journal.pone.0112610.s008
A30: Gao2014 | B30: sp29 | C30: Fern* | D30: Davallia trichomanoides | E30: F/H | F30: -140 | G30: -142 | H30: -125 | I30: -136 | K30: -139 | L30: -152 | O30: -57 | P30: =IF(OR(J30="",N30=""),"",1000*((1+J30/1000)/(1+N30/1000)-1)) | Q30: =IF(OR(K30="",N30=""),"",1000*((1+K30/1000)/(1+N30/1000)-1)) | R30: =IF(OR(L30="",N30=""),"",1000*((1+L30/1000)/(1+N30/1000)-1)) | S30: =IF(OR(J30="",M30=""),"",1000*((1+J30/1000)/(1+M30/1000)-1)) | T30: =IF(OR(K30="",M30=""),"",1000*((1+K30/1000)/(1+M30/1000)-1)) | U30: =IF(OR(L30="",M30=""),"",1000*((1+L30/1000)/(1+M30/1000)-1)) | V30: =IF(J30="","",1000*((1+J30/1000)/(1+O30/1000)-1)) | W30: =IF(K30="","",1000*((1+K30/1000)/(1+O30/1000)-1)) -> -86.956522 | X30: =IF(L30="","",1000*((1+L30/1000)/(1+O30/1000)-1)) -> -100.74231 | Y30: =IF(OR(J30="",K30=""),"",K30-J30) | Z30: =IF(OR(K30="",L30=""),"",L30-K30) -> -13 | AA30: 10.1371/journal.pone.0112610 | AB30: https://journals.plos.org/plosone/article?id=10.1371/journal.pone.0112610 | AC30: https://doi.org/10.1371/journal.pone.0112610.s008
A31: Gao2014 | B31: sp30 | C31: Gymn | D31: Taxodium distichum | E31: Tree | F31: -135 | G31: -144 | H31: -141 | J31: -155 | K31: -154 | L31: -137 | M31: -9.5 | N31: -44.8 | O31: -57 | P31: =IF(OR(J31="",N31=""),"",1000*((1+J31/1000)/(1+N31/1000)-1)) -> -115.36851 | Q31: =IF(OR(K31="",N31=""),"",1000*((1+K31/1000)/(1+N31/1000)-1)) -> -114.32161 | R31: =IF(OR(L31="",N31=""),"",1000*((1+L31/1000)/(1+N31/1000)-1)) -> -96.524288 | S31: =IF(OR(J31="",M31=""),"",1000*((1+J31/1000)/(1+M31/1000)-1)) -> -146.89551 | T31: =IF(OR(K31="",M31=""),"",1000*((1+K31/1000)/(1+M31/1000)-1)) -> -145.88592 | U31: =IF(OR(L31="",M31=""),"",1000*((1+L31/1000)/(1+M31/1000)-1)) -> -128.72287 | V31: =IF(J31="","",1000*((1+J31/1000)/(1+O31/1000)-1)) -> -103.92365 | W31: =IF(K31="","",1000*((1+K31/1000)/(1+O31/1000)-1)) -> -102.8632 | X31: =IF(L31="","",1000*((1+L31/1000)/(1+O31/1000)-1)) -> -84.835631 | Y31: =IF(OR(J31="",K31=""),"",K31-J31) -> 1 | Z31: =IF(OR(K31="",L31=""),"",L31-K31) -> 17 | AA31: 10.1371/journal.pone.0112610 | AB31: https://journals.plos.org/plosone/article?id=10.1371/journal.pone.0112610 | AC31: https://doi.org/10.1371/journal.pone.0112610.s008
A32: Gao2014 | B32: sp31 | C32: Gymn | D32: Abies homolepis | E32: Tree | G32: -147 | H32: -137 | J32: -141 | K32: -144 | L32: -109 | M32: -9.1 | N32: -30.9 | O32: -57 | P32: =IF(OR(J32="",N32=""),"",1000*((1+J32/1000)/(1+N32/1000)-1)) -> -113.61057 | Q32: =IF(OR(K32="",N32=""),"",1000*((1+K32/1000)/(1+N32/1000)-1)) -> -116.70622 | R32: =IF(OR(L32="",N32=""),"",1000*((1+L32/1000)/(1+N32/1000)-1)) -> -80.590238 | S32: =IF(OR(J32="",M32=""),"",1000*((1+J32/1000)/(1+M32/1000)-1)) -> -133.11131 | T32: =IF(OR(K32="",M32=""),"",1000*((1+K32/1000)/(1+M32/1000)-1)) -> -136.13886 | U32: =IF(OR(L32="",M32=""),"",1000*((1+L32/1000)/(1+M32/1000)-1)) -> -100.81744 | V32: =IF(J32="","",1000*((1+J32/1000)/(1+O32/1000)-1)) -> -89.077413 | W32: =IF(K32="","",1000*((1+K32/1000)/(1+O32/1000)-1)) -> -92.258749 | X32: =IF(L32="","",1000*((1+L32/1000)/(1+O32/1000)-1)) -> -55.14316 | Y32: =IF(OR(J32="",K32=""),"",K32-J32) -> -3 | Z32: =IF(OR(K32="",L32=""),"",L32-K32) -> 35 | AA32: 10.1371/journal.pone.0112610 | AB32: https://journals.plos.org/plosone/article?id=10.1371/journal.pone.0112610 | AC32: https://doi.org/10.1371/journal.pone.0112610.s008
A33: Gao2014 | B33: sp32 | C33: Gymn | D33: Metasequoia glyptostroboides | E33: Tree | F33: -162 | G33: -155 | H33: -143 | J33: -148 | K33: -154 | L33: -140 | M33: -15.7 | N33: -46.8 | O33: -57 | P33: =IF(OR(J33="",N33=""),"",1000*((1+J33/1000)/(1+N33/1000)-1)) -> -106.16869 | Q33: =IF(OR(K33="",N33=""),"",1000*((1+K33/1000)/(1+N33/1000)-1)) -> -112.46328 | R33: =IF(OR(L33="",N33=""),"",1000*((1+L33/1000)/(1+N33/1000)-1)) -> -97.775913 | S33: =IF(OR(J33="",M33=""),"",1000*((1+J33/1000)/(1+M33/1000)-1)) -> -134.41024 | T33: =IF(OR(K33="",M33=""),"",1000*((1+K33/1000)/(1+M33/1000)-1)) -> -140.50594 | U33: =IF(OR(L33="",M33=""),"",1000*((1+L33/1000)/(1+M33/1000)-1)) -> -126.28264 | V33: =IF(J33="","",1000*((1+J33/1000)/(1+O33/1000)-1)) -> -96.50053 | W33: =IF(K33="","",1000*((1+K33/1000)/(1+O33/1000)-1)) -> -102.8632 | X33: =IF(L33="","",1000*((1+L33/1000)/(1+O33/1000)-1)) -> -88.016967 | Y33: =IF(OR(J33="",K33=""),"",K33-J33) -> -6 | Z33: =IF(OR(K33="",L33=""),"",L33-K33) -> 14 | AA33: 10.1371/journal.pone.0112610 | AB33: https://journals.plos.org/plosone/article?id=10.1371/journal.pone.0112610 | AC33: https://doi.org/10.1371/journal.pone.0112610.s008
A34: Gao2014 | B34: sp33 | C34: Gymn | D34: Picea orientalis | E34: Tree | F34: -158 | G34: -141 | H34: -133 | I34: -137 | M34: -9.2 | N34: -36 | O34: -57 | P34: =IF(OR(J34="",N34=""),"",1000*((1+J34/1000)/(1+N34/1000)-1)) | Q34: =IF(OR(K34="",N34=""),"",1000*((1+K34/1000)/(1+N34/1000)-1)) | R34: =IF(OR(L34="",N34=""),"",1000*((1+L34/1000)/(1+N34/1000)-1)) | S34: =IF(OR(J34="",M34=""),"",1000*((1+J34/1000)/(1+M34/1000)-1)) | T34: =IF(OR(K34="",M34=""),"",1000*((1+K34/1000)/(1+M34/1000)-1)) | U34: =IF(OR(L34="",M34=""),"",1000*((1+L34/1000)/(1+M34/1000)-1)) | V34: =IF(J34="","",1000*((1+J34/1000)/(1+O34/1000)-1)) | W34: =IF(K34="","",1000*((1+K34/1000)/(1+O34/1000)-1)) | X34: =IF(L34="","",1000*((1+L34/1000)/(1+O34/1000)-1)) | Y34: =IF(OR(J34="",K34=""),"",K34-J34) | Z34: =IF(OR(K34="",L34=""),"",L34-K34) | AA34: 10.1371/journal.pone.0112610 | AB34: https://journals.plos.org/plosone/article?id=10.1371/journal.pone.0112610 | AC34: https://doi.org/10.1371/journal.pone.0112610.s008
A35: Gao2014 | B35: sp34 | C35: Gymn | D35: Ginkgo biloba | E35: Tree | F35: -197 | G35: -147 | H35: -154 | I35: -145 | J35: -149 | K35: -155 | L35: -138 | M35: -11.4 | N35: -46.7 | O35: -57 | P35: =IF(OR(J35="",N35=""),"",1000*((1+J35/1000)/(1+N35/1000)-1)) -> -107.31144 | Q35: =IF(OR(K35="",N35=""),"",1000*((1+K35/1000)/(1+N35/1000)-1)) -> -113.60537 | R35: =IF(OR(L35="",N35=""),"",1000*((1+L35/1000)/(1+N35/1000)-1)) -> -95.772579 | S35: =IF(OR(J35="",M35=""),"",1000*((1+J35/1000)/(1+M35/1000)-1)) -> -139.18673 | T35: =IF(OR(K35="",M35=""),"",1000*((1+K35/1000)/(1+M35/1000)-1)) -> -145.25592 | U35: =IF(OR(L35="",M35=""),"",1000*((1+L35/1000)/(1+M35/1000)-1)) -> -128.05988 | V35: =IF(J35="","",1000*((1+J35/1000)/(1+O35/1000)-1)) -> -97.560976 | W35: =IF(K35="","",1000*((1+K35/1000)/(1+O35/1000)-1)) -> -103.92365 | X35: =IF(L35="","",1000*((1+L35/1000)/(1+O35/1000)-1)) -> -85.896076 | Y35: =IF(OR(J35="",K35=""),"",K35-J35) -> -6 | Z35: =IF(OR(K35="",L35=""),"",L35-K35) -> 17 | AA35: 10.1371/journal.pone.0112610 | AB35: https://journals.plos.org/plosone/article?id=10.1371/journal.pone.0112610 | AC35: https://doi.org/10.1371/journal.pone.0112610.s008
A36: Gao2014 | B36: sp35 | C36: Gymn | D36: Ephedra gerardiana | E36: Shrub | F36: -129 | G36: -124 | H36: -141 | J36: -133 | K36: -139 | L36: -143 | M36: -9.7 | N36: -43.7 | O36: -57 | P36: =IF(OR(J36="",N36=""),"",1000*((1+J36/1000)/(1+N36/1000)-1)) -> -93.380738 | Q36: =IF(OR(K36="",N36=""),"",1000*((1+K36/1000)/(1+N36/1000)-1)) -> -99.65492 | R36: =IF(OR(L36="",N36=""),"",1000*((1+L36/1000)/(1+N36/1000)-1)) -> -103.83771 | S36: =IF(OR(J36="",M36=""),"",1000*((1+J36/1000)/(1+M36/1000)-1)) -> -124.50772 | T36: =IF(OR(K36="",M36=""),"",1000*((1+K36/1000)/(1+M36/1000)-1)) -> -130.5665 | U36: =IF(OR(L36="",M36=""),"",1000*((1+L36/1000)/(1+M36/1000)-1)) -> -134.60568 | V36: =IF(J36="","",1000*((1+J36/1000)/(1+O36/1000)-1)) -> -80.593849 | W36: =IF(K36="","",1000*((1+K36/1000)/(1+O36/1000)-1)) -> -86.956522 | X36: =IF(L36="","",1000*((1+L36/1000)/(1+O36/1000)-1)) -> -91.198303 | Y36: =IF(OR(J36="",K36=""),"",K36-J36) -> -6 | Z36: =IF(OR(K36="",L36=""),"",L36-K36) -> -4 | AA36: 10.1371/journal.pone.0112610 | AB36: https://journals.plos.org/plosone/article?id=10.1371/journal.pone.0112610 | AC36: https://doi.org/10.1371/journal.pone.0112610.s008
A37: Gao2014 | B37: sp36 | C37: Gymn | D37: Pinus parviflora | E37: Tree | F37: -183 | G37: -177 | H37: -180 | I37: -178 | J37: -151 | K37: -173 | L37: -172 | M37: -13.5 | N37: -50.7 | O37: -57 | P37: =IF(OR(J37="",N37=""),"",1000*((1+J37/1000)/(1+N37/1000)-1)) -> -105.6568 | Q37: =IF(OR(K37="",N37=""),"",1000*((1+K37/1000)/(1+N37/1000)-1)) -> -128.83177 | R37: =IF(OR(L37="",N37=""),"",1000*((1+L37/1000)/(1+N37/1000)-1)) -> -127.77836 | S37: =IF(OR(J37="",M37=""),"",1000*((1+J37/1000)/(1+M37/1000)-1)) -> -139.38165 | T37: =IF(OR(K37="",M37=""),"",1000*((1+K37/1000)/(1+M37/1000)-1)) -> -161.68272 | U37: =IF(OR(L37="",M37=""),"",1000*((1+L37/1000)/(1+M37/1000)-1)) -> -160.66903 | V37: =IF(J37="","",1000*((1+J37/1000)/(1+O37/1000)-1)) -> -99.681866 | W37: =IF(K37="","",1000*((1+K37/1000)/(1+O37/1000)-1)) -> -123.01166 | X37: =IF(L37="","",1000*((1+L37/1000)/(1+O37/1000)-1)) -> -121.95122 | Y37: =IF(OR(J37="",K37=""),"",K37-J37) -> -22 | Z37: =IF(OR(K37="",L37=""),"",L37-K37) -> 1 | AA37: 10.1371/journal.pone.0112610 | AB37: https://journals.plos.org/plosone/article?id=10.1371/journal.pone.0112610 | AC37: https://doi.org/10.1371/journal.pone.0112610.s008
A38: Gao2014 | B38: sp37 | C38: Eudic | D38: Bougainvillea 'Tahitian Dawn' | E38: CV | F38: -149 | G38: -138 | H38: -154 | I38: -147 | J38: -147 | K38: -161 | L38: -146 | M38: -87.9 | N38: -58.3 | O38: -57 | P38: =IF(OR(J38="",N38=""),"",1000*((1+J38/1000)/(1+N38/1000)-1)) -> -94.191356 | Q38: =IF(OR(K38="",N38=""),"",1000*((1+K38/1000)/(1+N38/1000)-1)) -> -109.05809 | R38: =IF(OR(L38="",N38=""),"",1000*((1+L38/1000)/(1+N38/1000)-1)) -> -93.129447 | S38: =IF(OR(J38="",M38=""),"",1000*((1+J38/1000)/(1+M38/1000)-1)) -> -64.795527 | T38: =IF(OR(K38="",M38=""),"",1000*((1+K38/1000)/(1+M38/1000)-1)) -> -80.144721 | U38: =IF(OR(L38="",M38=""),"",1000*((1+L38/1000)/(1+M38/1000)-1)) -> -63.699156 | V38: =IF(J38="","",1000*((1+J38/1000)/(1+O38/1000)-1)) -> -95.440085 | W38: =IF(K38="","",1000*((1+K38/1000)/(1+O38/1000)-1)) -> -110.28632 | X38: =IF(L38="","",1000*((1+L38/1000)/(1+O38/1000)-1)) -> -94.379639 | Y38: =IF(OR(J38="",K38=""),"",K38-J38) -> -14 | Z38: =IF(OR(K38="",L38=""),"",L38-K38) -> 15 | AA38: 10.1371/journal.pone.0112610 | AB38: https://journals.plos.org/plosone/article?id=10.1371/journal.pone.0112610 | AC38: https://doi.org/10.1371/journal.pone.0112610.s008
A39: Gao2014 | B39: sp38 | C39: Eudic | D39: Amsonia tabernaemontana | E39: F/H | F39: -152 | G39: -169 | H39: -187 | I39: -178 | J39: -154 | K39: -154 | L39: -165 | M39: -53 | N39: -50.1 | O39: -57 | P39: =IF(OR(J39="",N39=""),"",1000*((1+J39/1000)/(1+N39/1000)-1)) -> -109.37993 | Q39: =IF(OR(K39="",N39=""),"",1000*((1+K39/1000)/(1+N39/1000)-1)) -> -109.37993 | R39: =IF(OR(L39="",N39=""),"",1000*((1+L39/1000)/(1+N39/1000)-1)) -> -120.9601 | S39: =IF(OR(J39="",M39=""),"",1000*((1+J39/1000)/(1+M39/1000)-1)) -> -106.65259 | T39: =IF(OR(K39="",M39=""),"",1000*((1+K39/1000)/(1+M39/1000)-1)) -> -106.65259 | U39: =IF(OR(L39="",M39=""),"",1000*((1+L39/1000)/(1+M39/1000)-1)) -> -118.26822 | V39: =IF(J39="","",1000*((1+J39/1000)/(1+O39/1000)-1)) -> -102.8632 | W39: =IF(K39="","",1000*((1+K39/1000)/(1+O39/1000)-1)) -> -102.8632 | X39: =IF(L39="","",1000*((1+L39/1000)/(1+O39/1000)-1)) -> -114.5281 | Y39: =IF(OR(J39="",K39=""),"",K39-J39) -> 0 | Z39: =IF(OR(K39="",L39=""),"",L39-K39) -> -11 | AA39: 10.1371/journal.pone.0112610 | AB39: https://journals.plos.org/plosone/article?id=10.1371/journal.pone.0112610 | AC39: https://doi.org/10.1371/journal.pone.0112610.s008
A40: Gao2014 | B40: sp39 | C40: Eudic | D40: Galium odoratum | E40: F/H | F40: -152 | G40: -156 | H40: -147 | I40: -138 | J40: -160 | K40: -148 | M40: -21.1 | N40: -32.3 | O40: -57 | P40: =IF(OR(J40="",N40=""),"",1000*((1+J40/1000)/(1+N40/1000)-1)) -> -131.96239 | Q40: =IF(OR(K40="",N40=""),"",1000*((1+K40/1000)/(1+N40/1000)-1)) -> -119.56185 | R40: =IF(OR(L40="",N40=""),"",1000*((1+L40/1000)/(1+N40/1000)-1)) | S40: =IF(OR(J40="",M40=""),"",1000*((1+J40/1000)/(1+M40/1000)-1)) -> -141.89396 | T40: =IF(OR(K40="",M40=""),"",1000*((1+K40/1000)/(1+M40/1000)-1)) -> -129.6353 | U40: =IF(OR(L40="",M40=""),"",1000*((1+L40/1000)/(1+M40/1000)-1)) | V40: =IF(J40="","",1000*((1+J40/1000)/(1+O40/1000)-1)) -> -109.22587 | W40: =IF(K40="","",1000*((1+K40/1000)/(1+O40/1000)-1)) -> -96.50053 | X40: =IF(L40="","",1000*((1+L40/1000)/(1+O40/1000)-1)) | Y40: =IF(OR(J40="",K40=""),"",K40-J40) -> 12 | Z40: =IF(OR(K40="",L40=""),"",L40-K40) | AA40: 10.1371/journal.pone.0112610 | AB40: https://journals.plos.org/plosone/article?id=10.1371/journal.pone.0112610 | AC40: https://doi.org/10.1371/journal.pone.0112610.s008
...

Sheet Tipple2015_Treatments
A1: Study_ID | B1: Species | C1: Primary_Wax_Homologue | D1: RH_Treatment | E1: TreatmentWater_dD_permil | F1: ModelledLeafWater_dD_permil | G1: Wax_dD_permil | H1: Wax_SD_permil | I1: Eps_app_reported_permil | J1: Eps_app_SD_permil | K1: Eps_bio_reported_permil | L1: Eps_bio_SD_permil | M1: n | N1: Eps_app_exact_recalc_permil | O1: Eps_bio_exact_recalc_permil | P1: Reported_minus_exact_app_permil | Q1: Reported_minus_exact_bio_permil | R1: DOI | S1: Source_URL
A2: Tipple2015 | B2: Populus fremontii | C2: C29 | D2: High RH | E2: -121 | F2: -59 | G2: -221 | H2: 2 | I2: -114 | J2: 2 | K2: -172 | L2: 2 | M2: 5 | N2: =1000*((1+G2/1000)/(1+E2/1000)-1) -> -113.76564 | O2: =1000*((1+G2/1000)/(1+F2/1000)-1) -> -172.15728 | P2: =I2-N2 -> -0.23435722 | Q2: =K2-O2 -> 0.15727949 | R2: 10.1111/pce.12457 | S2: https://onlinelibrary.wiley.com/doi/10.1111/pce.12457
A3: Tipple2015 | B3: Populus fremontii | C3: C29 | D3: High RH | E3: -60 | F3: -34 | G3: -192 | H3: 2 | I3: -140 | J3: 3 | K3: -163 | L3: 3 | M3: 4 | N3: =1000*((1+G3/1000)/(1+E3/1000)-1) -> -140.42553 | O3: =1000*((1+G3/1000)/(1+F3/1000)-1) -> -163.56108 | P3: =I3-N3 -> 0.42553191 | Q3: =K3-O3 -> 0.5610766 | R3: 10.1111/pce.12457 | S3: https://onlinelibrary.wiley.com/doi/10.1111/pce.12457
A4: Tipple2015 | B4: Populus fremontii | C4: C29 | D4: High RH | E4: -5 | F4: -11 | G4: -166 | H4: 3 | I4: -162 | J4: 3 | K4: -156 | L4: 3 | M4: 5 | N4: =1000*((1+G4/1000)/(1+E4/1000)-1) -> -161.80905 | O4: =1000*((1+G4/1000)/(1+F4/1000)-1) -> -156.72396 | P4: =I4-N4 -> -0.19095477 | Q4: =K4-O4 -> 0.7239636 | R4: 10.1111/pce.12457 | S4: https://onlinelibrary.wiley.com/doi/10.1111/pce.12457
A5: Tipple2015 | B5: Populus fremontii | C5: C29 | D5: High RH | E5: 60 | F5: 16 | G5: -148 | H5: 1 | I5: -196 | J5: 1 | K5: -161 | L5: 1 | M5: 4 | N5: =1000*((1+G5/1000)/(1+E5/1000)-1) -> -196.22642 | O5: =1000*((1+G5/1000)/(1+F5/1000)-1) -> -161.41732 | P5: =I5-N5 -> 0.22641509 | Q5: =K5-O5 -> 0.41732283 | R5: 10.1111/pce.12457 | S5: https://onlinelibrary.wiley.com/doi/10.1111/pce.12457
A6: Tipple2015 | B6: Populus fremontii | C6: C29 | D6: High RH | E6: 114 | F6: 38 | G6: -118 | H6: 3 | I6: -208 | J6: 2 | K6: -150 | L6: 3 | M6: 4 | N6: =1000*((1+G6/1000)/(1+E6/1000)-1) -> -208.25853 | O6: =1000*((1+G6/1000)/(1+F6/1000)-1) -> -150.28902 | P6: =I6-N6 -> 0.25852783 | Q6: =K6-O6 -> 0.28901734 | R6: 10.1111/pce.12457 | S6: https://onlinelibrary.wiley.com/doi/10.1111/pce.12457
A7: Tipple2015 | B7: Populus fremontii | C7: C29 | D7: High RH | E7: 172 | F7: 62 | G7: -91 | H7: 2 | I7: -224 | J7: 2 | K7: -144 | L7: 2 | M7: 5 | N7: =1000*((1+G7/1000)/(1+E7/1000)-1) -> -224.40273 | O7: =1000*((1+G7/1000)/(1+F7/1000)-1) -> -144.0678 | P7: =I7-N7 -> 0.40273038 | Q7: =K7-O7 -> 0.06779661 | R7: 10.1111/pce.12457 | S7: https://onlinelibrary.wiley.com/doi/10.1111/pce.12457
A8: Tipple2015 | B8: Populus fremontii | C8: C29 | D8: Low RH | E8: -121 | F8: -49 | G8: -212 | H8: 0 | I8: -104 | J8: 0 | K8: -171 | L8: 0 | M8: 5 | N8: =1000*((1+G8/1000)/(1+E8/1000)-1) -> -103.52673 | O8: =1000*((1+G8/1000)/(1+F8/1000)-1) -> -171.39853 | P8: =I8-N8 -> -0.47326507 | Q8: =K8-O8 -> 0.39852787 | R8: 10.1111/pce.12457 | S8: https://onlinelibrary.wiley.com/doi/10.1111/pce.12457
A9: Tipple2015 | B9: Populus fremontii | C9: C29 | D9: Low RH | E9: -60 | F9: -6 | G9: -171 | H9: 1 | I9: -118 | J9: 1 | K9: -166 | L9: 1 | M9: 4 | N9: =1000*((1+G9/1000)/(1+E9/1000)-1) -> -118.08511 | O9: =1000*((1+G9/1000)/(1+F9/1000)-1) -> -165.99598 | P9: =I9-N9 -> 0.085106383 | Q9: =K9-O9 -> -0.0040241449 | R9: 10.1111/pce.12457 | S9: https://onlinelibrary.wiley.com/doi/10.1111/pce.12457
A10: Tipple2015 | B10: Populus fremontii | C10: C29 | D10: Low RH | E10: -5 | F10: 34 | G10: -135 | H10: 2 | I10: -131 | J10: 2 | K10: -163 | L10: 2 | M10: 9 | N10: =1000*((1+G10/1000)/(1+E10/1000)-1) -> -130.65327 | O10: =1000*((1+G10/1000)/(1+F10/1000)-1) -> -163.44294 | P10: =I10-N10 -> -0.34673367 | Q10: =K10-O10 -> 0.44294004 | R10: 10.1111/pce.12457 | S10: https://onlinelibrary.wiley.com/doi/10.1111/pce.12457
A11: Tipple2015 | B11: Populus fremontii | C11: C29 | D11: Low RH | E11: 60 | F11: 80 | G11: -93 | H11: 7 | I11: -145 | J11: 6 | K11: -160 | L11: 6 | M11: 6 | N11: =1000*((1+G11/1000)/(1+E11/1000)-1) -> -144.33962 | O11: =1000*((1+G11/1000)/(1+F11/1000)-1) -> -160.18519 | P11: =I11-N11 -> -0.66037736 | Q11: =K11-O11 -> 0.18518519 | R11: 10.1111/pce.12457 | S11: https://onlinelibrary.wiley.com/doi/10.1111/pce.12457
A12: Tipple2015 | B12: Populus fremontii | C12: C29 | D12: Low RH | E12: 114 | F12: 119 | G12: -76 | H12: 5 | I12: -171 | J12: 5 | K12: -174 | L12: 5 | M12: 7 | N12: =1000*((1+G12/1000)/(1+E12/1000)-1) -> -170.55655 | O12: =1000*((1+G12/1000)/(1+F12/1000)-1) -> -174.26273 | P12: =I12-N12 -> -0.44344704 | Q12: =K12-O12 -> 0.26273458 | R12: 10.1111/pce.12457 | S12: https://onlinelibrary.wiley.com/doi/10.1111/pce.12457
A13: Tipple2015 | B13: Populus fremontii | C13: C29 | D13: Low RH | E13: 172 | F13: 160 | G13: -35 | H13: 5 | I13: -177 | J13: 4 | K13: -168 | L13: 4 | M13: 13 | N13: =1000*((1+G13/1000)/(1+E13/1000)-1) -> -176.62116 | O13: =1000*((1+G13/1000)/(1+F13/1000)-1) -> -168.10345 | P13: =I13-N13 -> -0.37883959 | Q13: =K13-O13 -> 0.10344828 | R13: 10.1111/pce.12457 | S13: https://onlinelibrary.wiley.com/doi/10.1111/pce.12457
... A25: Tipple2015 | B25: Betula occidentalis | C25: C31 | D25: Low RH | E25: 172 | F25: 160 | G25: -20 | H25: 6 | I25: -164 | J25: 5 | K25: -155 | L25: 5 | M25: 11 | N25: =1000*((1+G25/1000)/(1+E25/1000)-1) -> -163.82253 | O25: =1000*((1+G25/1000)/(1+F25/1000)-1) -> -155.17241 | P25: =I25-N25 -> -0.1774744 | Q25: =K25-O25 -> 0.17241379 | R25: 10.1111/pce.12457 | S25: https://onlinelibrary.wiley.com/doi/10.1111/pce.12457

Sheet Literature_Targets
A1: Study_ID | B1: Type | C1: Observation | D1: Value | E1: Uncertainty_or_Range | F1: n | G1: DOI | H1: Source_URL
A2: Tipple2015 | B2: εbio overall | C2: Populus fremontii leaf-water→C29 wax biosynthetic fractionation | D2: -164‰ | E2: ±10‰ | G2: 10.1111/pce.12457 | H2: https://onlinelibrary.wiley.com/doi/10.1111/pce.12457
A3: Tipple2015 | B3: εbio overall | C3: Betula occidentalis leaf-water→C31 wax biosynthetic fractionation | D3: -150‰ | E3: ±9‰ | G3: 10.1111/pce.12457 | H3: https://onlinelibrary.wiley.com/doi/10.1111/pce.12457
A4: Feakins2016 | B4: εwax/source | C4: C29 n-alkane fractionation relative to measured source/xylem water in humid tropical forest | D4: -129‰ | E4: ±2‰ s.e.m.; reported σ≈22‰ | F4: 136 | G4: 10.1016/j.gca.2016.03.018 | H4: https://doi.org/10.1016/j.gca.2016.03.018
A5: Kahmen2013_I | B5: Leaf-water transfer | C5: Dicot n-alkanes record approximately the full leaf-water evaporative D enrichment | D5: ~100% transfer | E5: qualitative/experimental | G5: 10.1016/j.gca.2012.09.003 | H5: https://doi.org/10.1016/j.gca.2012.09.003
A6: Kahmen2013_I | B6: Leaf-water transfer | C6: Monocot n-alkanes record only part of leaf-water evaporative D enrichment | D6: 18–68% transfer | E6: reported range | G6: 10.1016/j.gca.2012.09.003 | H6: https://doi.org/10.1016/j.gca.2012.09.003
A7: Sachse2010 | B7: Seasonality | C7: Leaf-wax n-alkanes changed ~20‰ across season while source/leaf water varied ~40‰ | D7: ~20‰ wax change | E7: ~40‰ water variation | G7: 10.1016/j.gca.2010.08.033 | H7: https://doi.org/10.1016/j.gca.2010.08.033
A8: Liu2016 | B8: Taxonomic apparent fractionation | C8: Northern Hemisphere synthesis average εwax-p for monocotyledonous species | D8: -140‰ | E8: study synthesis | G8: 10.1038/srep19711 | H8: https://www.nature.com/articles/srep19711
A9: Liu2016 | B9: Taxonomic apparent fractionation | C9: Northern Hemisphere synthesis average εwax-p for dicotyledonous species | D9: -107‰ | E9: study synthesis | G9: 10.1038/srep19711 | H9: https://www.nature.com/articles/srep19711
A10: Baan2025 | B10: Cross-pathway covariance | C10: Pairwise δ2H relationships among different organic compounds were weak | D10: R² < 0.26 | E10: reported maximum relationship strength | F10: 179 | G10: 10.1111/nph.20430 | H10: https://nph.onlinelibrary.wiley.com/doi/10.1111/nph.20430
A11: Tipple2013 | B11: Timing | C11: Leaf-wax n-alkanes primarily record plant-water conditions during leaf flush | D11: ~2-week formation window | E11: wax remained essentially fixed over following ~19 weeks | G11: 10.1073/pnas.1213875110 | H11: https://www.pnas.org/doi/10.1073/pnas.1213875110
A12: Ardenghi2024 | B12: Field εwax/MAP | C12: C3 graminoid group-average C29/MAP net fractionation | D12: -163 to -175‰ | E12: site/season group averages | G12: 10.3389/feart.2024.1359157 | H12: https://www.frontiersin.org/journals/earth-science/articles/10.3389/feart.2024.1359157/full
A13: Baan2023a | B13: Metabolic sensitivity | C13: Hydrogen-isotope fractionation responds differently among plant compound classes under altered metabolism | D13: compound-specific response | E13: qualitative until supplement import | G13: 10.1016/j/phytochem.2022.113563 | H13: https://www.sciencedirect.com/science/article/pii/S0031942222004794

Sheet Study_Registry
A1: Study_ID | B1: Year | C1: Citation_Short | D1: Species/Scope | E1: Water_Data | F1: Lipid_Data | G1: Homologue_Detail | H1: Controlled_Manipulation | I1: Rows_In_Workbook | J1: DOI | K1: Article_URL | L1: Data_URL
A2: Gao2014 | B2: 2014 | C2: Gao et al. 2014 | D2: 102 vascular plant species | E2: Leaf + xylem water | F2: n-alkanes and n-acids | G2: C27/C29/C31 n-alkanes | H2: Common environment | I2: 102 | J2: 10.1371/journal.pone.0112610 | K2: https://journals.plos.org/plosone/article?id=10.1371/journal.pone.0112610 | L2: https://doi.org/10.1371/journal.pone.0112610.s008
A3: Tipple2015 | B3: 2015 | C3: Tipple et al. 2015 | D3: Populus fremontii; Betula occidentalis | E3: Treatment + modelled leaf water | F3: C29 (Populus), C31 (Betula) | G3: Single dominant homologue per species | H3: 6 source waters × 2 RH treatments | I3: 24 | J3: 10.1111/pce.12457 | K3: https://onlinelibrary.wiley.com/doi/10.1111/pce.12457
A4: Liu2016 | B4: 2016 | C4: Liu et al. 2016 | D4: Monocotyledonous and dicotyledonous higher plants | E4: Measured leaf water in supplementary experiments | F4: C29 n-alkane; compiled n-alkanes | G4: C29 in paired experiments | H4: Within-leaf position; taxonomy | I4: 64 | J4: 10.1038/srep19711 | K4: https://www.nature.com/articles/srep19711 | L4: https://media.springernature.com/original/springer-static/esm/art%3A10.1038%2Fsrep19711/MediaObjects/41598_2016_BFsrep19711_MOESM1_ESM.pdf
A5: Tipple2021_PANGAEA | B5: 2021 | C5: Tipple 2021 PANGAEA | D5: Northern California plant and soil samples | E5: Paired water is in the broader PANGAEA bundle, not this leaf-wax table | F5: C25/C27/C29/C31 n-alkanes | G5: Multi-homologue | H5: Elevation/environmental gradient | I5: 97 | J5: 10.1594/PANGAEA.932017 | K5: https://doi.pangaea.de/10.1594/PANGAEA.932017 | L5: https://doi.pangaea.de/10.1594/PANGAEA.932017
A6: Ardenghi2024 | B6: 2024 | C6: Ardenghi et al. 2024 | D6: 13 fen plant species; two Greek wetlands | E6: Soil/surface/internal water reported in study | F6: C29 and concentration-weighted n-alkanes | G6: C29 + CMWA | H6: Spring/summer; functional groups | I6: 27 | J6: 10.3389/feart.2024.1359157 | K6: https://www.frontiersin.org/journals/earth-science/articles/10.3389/feart.2024.1359157/full | L6: https://www.frontiersin.org/journals/earth-science/articles/10.3389/feart.2024.1359157/full
A7: Lehmann2024 | B7: 2024 | C7: Lehmann et al. 2024 | D7: Nicotiana sylvestris; two experiments | E7: Water isotopes + biochemical/biophysical traits | F7: Leaf n-alkanes + carbohydrates | G7: Dataset includes n-alkanes | H7: N-species fertilization; starch-deficiency knockout | I7: 0 | J7: 10.1126/sciadv.adl3591 | K7: https://www.science.org/doi/10.1126/sciadv.adl3591 | L7: https://doi.org/10.5061/dryad.1zcrjdg04
A8: Feakins2016 | B8: 2016 | C8: Feakins et al. 2016 | D8: 176 individuals; 32 species; five plots | E8: Xylem + leaf water | F8: Leaf wax n-alkanes | G8: C29 emphasized | H8: Elevation/environmental gradient | I8: 0 | J8: 10.1016/j.gca.2016.03.018 | K8: https://doi.org/10.1016/j.gca.2016.03.018
A9: Kahmen2013_I | B9: 2013 | C9: Kahmen et al. 2013 | D9: Five angiosperm species | E9: Source/leaf-water enrichment | F9: Leaf wax n-alkanes | G9: Multiple n-alkanes | H9: Humidity / evaporative enrichment | I9: 0 | J9: 10.1016/j.gca.2012.09.003 | K9: https://doi.org/10.1016/j.gca.2012.09.003
A10: Gamarra2016 | B10: 2016 | C10: Gamarra et al. 2016 | D10: C3 and C4 grasses | E10: Leaf water | F10: Leaf wax n-alkanes | G10: Multiple n-alkanes | H10: Evaporative enrichment / photosynthetic type | I10: 0 | J10: 10.1111/pce.12789 | K10: https://onlinelibrary.wiley.com/doi/10.1111/pce.12789
A11: Baan2025 | B11: 2025 | C11: Baan et al. 2025 | D11: 179 eudicot species plus additional compound subset | E11: Leaf-water/organic-compound context | F11: n-alkanes, cellulose and other plant compounds | G11: Compound-level | H11: Species/phylogeny | I11: 0 | J11: 10.1111/nph.20430 | K11: https://nph.onlinelibrary.wiley.com/doi/10.1111/nph.20430
A12: Tipple2013 | B12: 2013 | C12: Tipple et al. 2013 | D12: Populus angustifolia | E12: Xylem + leaf + stream + atmospheric water | F12: Leaf wax n-alkanes | G12: Time series | H12: Seasonal leaf development | I12: 0 | J12: 10.1073/pnas.1213875110 | K12: https://www.pnas.org/doi/10.1073/pnas.1213875110
A13: Sachse2010 | B13: 2010 | C13: Sachse et al. 2010 | D13: Hordeum vulgare | E13: Soil + leaf water | F13: Leaf wax n-alkanes | G13: Leaf-generation resolved | H13: Season / leaf development | I13: 0 | J13: 10.1016/j.gca.2010.08.033 | K13: https://doi.org/10.1016/j.gca.2010.08.033
A14: McInerney2011 | B14: 2011 | C14: McInerney et al. 2011 | D14: C3 and C4 grasses | E14: Source/plant water context | F14: Leaf wax n-alkanes | G14: High-MW n-alkanes | H14: Transpiration / physiology | I14: 0 | J14: 10.1016/j.gca.2010.10.022 | K14: https://doi.org/10.1016/j.gca.2010.10.022
A15: Zhou2016 | B15: 2016 | C15: Zhou et al. 2016 | D15: C3 and C4 land plants | E15: Plant-water context | F15: Plant lipids | G15: Multiple lipid classes | H15: Photosynthetic pathway | I15: 0 | J15: 10.1111/pce.12821 | K15: https://doi.org/10.1111/pce.12821
A16: Eley2014 | B16: 2014 | C16: Eley et al. 2014 | D16: Coastal saltmarsh plants | E16: Plant-water context | F16: Leaf wax n-alkanes | G16: Multiple n-alkanes | H16: Species/environment | I16: 0 | J16: 10.1016/j.gca.2013.11.045 | K16: https://doi.org/10.1016/j.gca.2013.11.045
A17: Eley2018 | B17: 2018 | C17: Eley et al. 2018 | D17: Saltmarsh plants | E17: Plant-water context | F17: Fatty acids, phytol and comparison with n-alkanes | G17: Compound-specific | H17: Species/environment | I17: 0 | J17: 10.1029/2018JG004403 | K17: https://agupubs.onlinelibrary.wiley.com/doi/full/10.1029/2018JG004403
A18: Baan2023a | B18: 2023 | C18: Baan et al. 2023a | D18: Plant compounds under altered metabolism | E18: Water/biochemical context | F18: Multiple plant compounds including acetogenic lipids | G18: Compound-specific | H18: Metabolic perturbation | I18: 0 | J18: 10.1016/j.phytochem.2022.113563 | K18: https://www.sciencedirect.com/science/article/pii/S0031942222004794
A19: Baan2023b | B19: 2023 | C19: Baan et al. 2023b | D19: Multiple plant species | E19: Plant water / organic compound context | F19: Multiple organic compounds | G19: Compound-specific | H19: Species | I19: 0 | J19: 10.1016/j.gca.2023.04.013 | K19: https://doi.org/10.1016/j.gca.2023.04.013

Sheet Data_Dictionary
A1: Sheet_or_Field | B1: Category | C1: Definition | D1: Units_or_Values
A2: Gao2014_Samples | B2: Dataset | C2: Common-garden 102-species water and lipid isotope dataset | D2: per mil VSMOW
A3: Tipple2015_Treatments | B3: Dataset | C3: Controlled source-water × humidity treatment means | D3: per mil VSMOW
A4: Liu2016_Segmented | B4: Dataset | C4: Paired local leaf-water and C29 δD along leaf blades | D4: per mil VSMOW
A5: Liu2016_WholeLeaf | B5: Dataset | C5: Whole-leaf paired leaf-water and wax δD observations | D5: per mil VSMOW
A6: Tipple2021_PANGAEA | B6: Dataset | C6: Northern California plant multi-homologue leaf-wax data | D6: per mil VSMOW
A7: Ardenghi2024_Epsilon | B7: Dataset | C7: Species-season mean net fractionation relative to MAP | D7: per mil
A8: Eps_*_exact | B8: Derived metric | C8: 1000*((1+δD_product/1000)/(1+δD_water/1000)-1) | D8: per mil
